// Part 1
addHello(String user) {
  return 'Hello $user';
}

// Part 2
// Call the provided async function fetchUsername()
// to return the username.
greetUser() {
  return fetchUsername().then((username) => addHello(username));
}

// Part 3
// Call the provided async function logoutUser()
// to log out the user.
sayGoodbye() async {
  try {
    String message = await logoutUser();
    return '$message Thanks, see you next time';
  } catch (e) {
    return 'Thanks, see you next time';
  }
}

// The following functions are provided to you to use in your solutions.

Future<String> fetchUsername() => Future.delayed(_halfSecond, () => 'Jean');

Future<String> logoutUser() => Future.delayed(_halfSecond, _failOnce);

// The following code is used to test and provide feedback on your solution.
// There is no need to read or modify it.

void main() async {
  const didNotImplement =
      'Test failed! Did you forget to implement or return from';

  final List<String> messages = [];

  print('Testing...');
  try {
    messages
      ..add(
        _makeReadable(
          testLabel: 'Part 1',
          testResult: await _asyncEquals(
            expected: 'Hello Jerry',
            actual: addHello('Jerry'),
            typoKeyword: 'Jerry',
          ),
          readableErrors: {
            _typoMessage: _typoMessage,
            'null': '$didNotImplement addHello?',
            'Hello Instance of \'Future<String>\'':
                'Looks like you forgot to use the \'await\' keyword!',
            'Hello Instance of \'_Future<String>\'':
                'Looks like you forgot to use the \'await\' keyword!',
          },
        ),
      )
      ..add(
        _makeReadable(
          testLabel: 'Part 2',
          testResult: await _asyncEquals(
            expected: 'Hello Jean',
            actual: await greetUser(),
            typoKeyword: 'Jean',
          ),
          readableErrors: {
            _typoMessage: _typoMessage,
            'null': '$didNotImplement greetUser?',
            'HelloJean':
                'Looks like you forgot the space between \'Hello\' and \'Jean\'',
            'Hello Instance of \'Future<String>\'':
                'Looks like you forgot to use the \'await\' keyword!',
            'Hello Instance of \'_Future<String>\'':
                'Looks like you forgot to use the \'await\' keyword!',
            '{Closure: (String) => dynamic from Function \'addHello\': static.(await fetchUsername())}':
                'Did you place the \'\$\' character correctly?',
            '{Closure \'addHello\'(await fetchUsername())}':
                'Did you place the \'\$\' character correctly?',
          },
        ),
      )
      ..add(
        _makeReadable(
          testLabel: 'Part 3',
          testResult: await _asyncDidCatchException(sayGoodbye),
          readableErrors: {
            _typoMessage:
                '$_typoMessage. Did you add the text \'Thanks, see you next time\'?',
            'null': '$didNotImplement sayGoodbye?',
            _noCatch:
                'Did you remember to call logoutUser within a try/catch block?',
            'Instance of \'Future<String>\' Thanks, see you next time':
                'Did you remember to use the \'await\' keyword in the sayGoodbye function?',
            'Instance of \'_Future<String>\' Thanks, see you next time':
                'Did you remember to use the \'await\' keyword in the sayGoodbye function?',
          },
        ),
      )
      ..add(
        _makeReadable(
          testLabel: 'Part 3',
          testResult: await _asyncEquals(
            expected: 'Success! Thanks, see you next time',
            actual: await sayGoodbye(),
            typoKeyword: 'Success',
          ),
          readableErrors: {
            _typoMessage:
                '$_typoMessage. Did you add the text \'Thanks, see you next time\'?',
            'null': '$didNotImplement sayGoodbye?',
            _noCatch:
                'Did you remember to call logoutUser within a try/catch block?',
            'Instance of \'Future<String>\' Thanks, see you next time':
                'Did you remember to use the \'await\' keyword in the sayGoodbye function?',
            'Instance of \'_Future<String>\' Thanks, see you next time':
                'Did you remember to use the \'await\' keyword in the sayGoodbye function?',
            'Instance of \'_Exception\'':
                'CAUGHT Did you remember to return a string?',
          },
        ),
      )
      ..removeWhere((m) => m.contains(_passed))
      ..toList();

    if (messages.isEmpty) {
      print('Success. All tests passed!');
    } else {
      messages.forEach(print);
    }
  } catch (e) {
    print('Tried to run solution, but received an exception: $e');
  }
}

// Test helpers.
String _makeReadable({
  required String testResult,
  required Map<String, String> readableErrors,
  required String testLabel,
}) {
  String? readable;
  if (readableErrors.containsKey(testResult)) {
    readable = readableErrors[testResult];
    return '$testLabel $readable';
  } else if ((testResult != _passed) && (testResult.length < 18)) {
    readable = _typoMessage;
    return '$testLabel $readable';
  } else {
    return '$testLabel $testResult';
  }
}

Future<String> _asyncEquals({
  required String expected,
  required dynamic actual,
  required String typoKeyword,
}) async {
  final strActual = actual is String ? actual : actual.toString();
  try {
    if (expected == actual) {
      return _passed;
    } else if (strActual.contains(typoKeyword)) {
      return _typoMessage;
    } else {
      return strActual;
    }
  } catch (e) {
    return e.toString();
  }
}

Future<String> _asyncDidCatchException(Function fn) async {
  var caught = true;
  try {
    await fn();
  } on Exception catch (_) {
    caught = false;
  }

  if (caught == true) {
    return _passed;
  } else {
    return _noCatch;
  }
}

const _typoMessage = 'Test failed! Check for typos in your return value';
const _passed = 'PASSED';
const _noCatch = 'NO_CATCH';
const _halfSecond = Duration(milliseconds: 500);

String _failOnce() {
  if (_logoutSucceeds) {
    return 'Success!';
  } else {
    _logoutSucceeds = true;
    throw Exception('Logout failed');
  }
}

bool _logoutSucceeds = false;
